<Type Name="TargetInvocationException" FullName="System.Reflection.TargetInvocationException">
  <Metadata>
    <Meta Name="ms.openlocfilehash" Value="4de71b8afd037417420fabfe4c7f744581ff2a10" />
    <Meta Name="ms.sourcegitcommit" Value="d31dc2ede16f6f7bc64e90d9f897ff54c4e3869b" />
    <Meta Name="ms.translationtype" Value="HT" />
    <Meta Name="ms.contentlocale" Value="ru-RU" />
    <Meta Name="ms.lasthandoff" Value="04/03/2018" />
  </Metadata>
  <TypeSignature Language="C#" Value="public sealed class TargetInvocationException : ApplicationException" />
  <TypeSignature Language="ILAsm" Value=".class public auto ansi serializable sealed beforefieldinit TargetInvocationException extends System.ApplicationException" />
  <TypeSignature Language="DocId" Value="T:System.Reflection.TargetInvocationException" />
  <TypeSignature Language="VB.NET" Value="Public NotInheritable Class TargetInvocationException&#xA;Inherits ApplicationException" />
  <TypeSignature Language="C++ CLI" Value="public ref class TargetInvocationException sealed : ApplicationException" />
  <AssemblyInfo>
    <AssemblyName>System.Reflection</AssemblyName>
    <AssemblyVersion>4.0.0.0</AssemblyVersion>
    <AssemblyVersion>4.0.10.0</AssemblyVersion>
    <AssemblyVersion>4.1.0.0</AssemblyVersion>
  </AssemblyInfo>
  <AssemblyInfo>
    <AssemblyName>mscorlib</AssemblyName>
    <AssemblyVersion>2.0.5.0</AssemblyVersion>
    <AssemblyVersion>4.0.0.0</AssemblyVersion>
  </AssemblyInfo>
  <AssemblyInfo>
    <AssemblyName>netstandard</AssemblyName>
    <AssemblyVersion>2.0.0.0</AssemblyVersion>
  </AssemblyInfo>
  <AssemblyInfo>
    <AssemblyName>System.Runtime</AssemblyName>
    <AssemblyVersion>4.2.0.0</AssemblyVersion>
    <AssemblyVersion>4.2.1.0</AssemblyVersion>
  </AssemblyInfo>
  <Base>
    <BaseTypeName>System.Exception</BaseTypeName>
    <BaseTypeName FrameworkAlternate="netframework-4.5">System.ApplicationException</BaseTypeName>
  </Base>
  <Interfaces />
  <Attributes>
    <Attribute>
      <AttributeName>System.Runtime.InteropServices.ComVisible(true)</AttributeName>
    </Attribute>
  </Attributes>
  <Docs>
    <summary>
      <span data-ttu-id="da67f-101">Исключение выдается методами, вызываемыми средствами отражения.</span>
      <span class="sxs-lookup">
        <span data-stu-id="da67f-101">The exception that is thrown by methods invoked through reflection.</span>
      </span>
      <span data-ttu-id="da67f-102">Этот класс не наследуется.</span>
      <span class="sxs-lookup">
        <span data-stu-id="da67f-102">This class cannot be inherited.</span>
      </span>
    </summary>
    <remarks>
      <format type="text/markdown"><![CDATA[  
  
## Remarks  
 <span data-ttu-id="da67f-103">Дополнительные сведения см. в разделе <xref:System.Reflection.MethodBase.Invoke%2A>.</span><span class="sxs-lookup"><span data-stu-id="da67f-103">For more information, see <xref:System.Reflection.MethodBase.Invoke%2A>.</span></span>  
  
 <span data-ttu-id="da67f-104">`TargetInvocationException` использует COR_E_TARGETINVOCATION HRESULT, который имеет значение 0x80131604.</span><span class="sxs-lookup"><span data-stu-id="da67f-104">`TargetInvocationException` uses the HRESULT COR_E_TARGETINVOCATION which has the value 0x80131604.</span></span>  
  
 <span data-ttu-id="da67f-105">При создании `TargetInvocationException` передается ссылка на исключение выдано методом, вызываемыми средствами отражения.</span><span class="sxs-lookup"><span data-stu-id="da67f-105">When created, the `TargetInvocationException` is passed a reference to the exception thrown by the method invoked through reflection.</span></span> <span data-ttu-id="da67f-106"><xref:System.Exception.InnerException%2A> Базовое исключение заносится в свойство.</span><span class="sxs-lookup"><span data-stu-id="da67f-106">The <xref:System.Exception.InnerException%2A> property holds the underlying exception.</span></span>  
  
 ]]></format>
    </remarks>
    <altmember cref="P:System.Exception.InnerException" />
    <altmember cref="T:System.Exception" />
  </Docs>
  <Members>
    <MemberGroup MemberName=".ctor">
      <AssemblyInfo>
        <AssemblyName>System.Reflection</AssemblyName>
        <AssemblyVersion>4.0.0.0</AssemblyVersion>
        <AssemblyVersion>4.0.10.0</AssemblyVersion>
        <AssemblyVersion>4.1.0.0</AssemblyVersion>
      </AssemblyInfo>
      <Docs>
        <summary>
          <span data-ttu-id="da67f-107">Инициализирует новый экземпляр класса <see cref="T:System.Reflection.TargetInvocationException" />.</span>
          <span class="sxs-lookup">
            <span data-stu-id="da67f-107">Initializes a new instance of the <see cref="T:System.Reflection.TargetInvocationException" /> class.</span>
          </span>
        </summary>
      </Docs>
    </MemberGroup>
    <Member MemberName=".ctor">
      <MemberSignature Language="C#" Value="public TargetInvocationException (Exception inner);" />
      <MemberSignature Language="ILAsm" Value=".method public hidebysig specialname rtspecialname instance void .ctor(class System.Exception inner) cil managed" />
      <MemberSignature Language="DocId" Value="M:System.Reflection.TargetInvocationException.#ctor(System.Exception)" />
      <MemberSignature Language="VB.NET" Value="Public Sub New (inner As Exception)" />
      <MemberSignature Language="C++ CLI" Value="public:&#xA; TargetInvocationException(Exception ^ inner);" />
      <MemberType>Constructor</MemberType>
      <AssemblyInfo>
        <AssemblyName>System.Reflection</AssemblyName>
        <AssemblyVersion>4.0.0.0</AssemblyVersion>
        <AssemblyVersion>4.0.10.0</AssemblyVersion>
        <AssemblyVersion>4.1.0.0</AssemblyVersion>
      </AssemblyInfo>
      <AssemblyInfo>
        <AssemblyName>mscorlib</AssemblyName>
        <AssemblyVersion>2.0.5.0</AssemblyVersion>
        <AssemblyVersion>4.0.0.0</AssemblyVersion>
      </AssemblyInfo>
      <AssemblyInfo>
        <AssemblyName>netstandard</AssemblyName>
        <AssemblyVersion>2.0.0.0</AssemblyVersion>
      </AssemblyInfo>
      <AssemblyInfo>
        <AssemblyName>System.Runtime</AssemblyName>
        <AssemblyVersion>4.2.0.0</AssemblyVersion>
        <AssemblyVersion>4.2.1.0</AssemblyVersion>
      </AssemblyInfo>
      <Parameters>
        <Parameter Name="inner" Type="System.Exception" />
      </Parameters>
      <Docs>
        <param name="inner">
          <span data-ttu-id="da67f-108">Исключение, которое является причиной текущего исключения.</span>
          <span class="sxs-lookup">
            <span data-stu-id="da67f-108">The exception that is the cause of the current exception.</span>
          </span>
          <span data-ttu-id="da67f-109">Если значение параметра <c>inner</c> не равно <see langword="null" />, текущее исключение возникает в блоке <see langword="catch" />, обрабатывающем внутреннее исключение.</span>
          <span class="sxs-lookup">
            <span data-stu-id="da67f-109">If the <c>inner</c> parameter is not <see langword="null" />, the current exception is raised in a <see langword="catch" /> block that handles the inner exception.</span>
          </span>
        </param>
        <summary>
          <span data-ttu-id="da67f-110">Инициализирует новый экземпляр класса <see cref="T:System.Reflection.TargetInvocationException" /> со ссылкой на внутреннее исключение, которое является причиной данного исключения.</span>
          <span class="sxs-lookup">
            <span data-stu-id="da67f-110">Initializes a new instance of the <see cref="T:System.Reflection.TargetInvocationException" /> class with a reference to the inner exception that is the cause of this exception.</span>
          </span>
        </summary>
        <remarks>
          <format type="text/markdown"><![CDATA[  
  
## Remarks  
 <span data-ttu-id="da67f-111">Исключение, созданное как прямой результат предыдущего исключения, должно содержать в свойстве <xref:System.Exception.InnerException%2A> ссылку на предыдущее исключение.</span><span class="sxs-lookup"><span data-stu-id="da67f-111">An exception that is thrown as a direct result of a previous exception should include a reference to the previous exception in the <xref:System.Exception.InnerException%2A> property.</span></span> <span data-ttu-id="da67f-112">Свойство <xref:System.Exception.InnerException%2A> возвращает значение, переданное конструктору, или значение `null`, если свойство <xref:System.Exception.InnerException%2A> не передает конструктору значение внутреннего исключения.</span><span class="sxs-lookup"><span data-stu-id="da67f-112">The <xref:System.Exception.InnerException%2A> property returns the same value that is passed into the constructor, or `null` if the <xref:System.Exception.InnerException%2A> property does not supply the inner exception value to the constructor.</span></span>  
  
 <span data-ttu-id="da67f-113">В следующей таблице представлены исходные значения свойств экземпляра класса <xref:System.Reflection.TargetInvocationException>.</span><span class="sxs-lookup"><span data-stu-id="da67f-113">The following table shows the initial property values for an instance of <xref:System.Reflection.TargetInvocationException>.</span></span>  
  
|<span data-ttu-id="da67f-114">Свойство.</span><span class="sxs-lookup"><span data-stu-id="da67f-114">Property</span></span>|<span data-ttu-id="da67f-115">Значение</span><span class="sxs-lookup"><span data-stu-id="da67f-115">Value</span></span>|  
|--------------|-----------|  
|<xref:System.Exception.InnerException%2A>|<span data-ttu-id="da67f-116">Ссылка на внутреннее исключение.</span><span class="sxs-lookup"><span data-stu-id="da67f-116">The inner exception reference.</span></span>|  
|<xref:System.Exception.Message%2A>|<span data-ttu-id="da67f-117">Строка сообщения об ошибке.</span><span class="sxs-lookup"><span data-stu-id="da67f-117">The error message string.</span></span>|  
  
 ]]></format>
        </remarks>
        <altmember cref="T:System.Exception" />
      </Docs>
    </Member>
    <Member MemberName=".ctor">
      <MemberSignature Language="C#" Value="public TargetInvocationException (string message, Exception inner);" />
      <MemberSignature Language="ILAsm" Value=".method public hidebysig specialname rtspecialname instance void .ctor(string message, class System.Exception inner) cil managed" />
      <MemberSignature Language="DocId" Value="M:System.Reflection.TargetInvocationException.#ctor(System.String,System.Exception)" />
      <MemberSignature Language="VB.NET" Value="Public Sub New (message As String, inner As Exception)" />
      <MemberSignature Language="C++ CLI" Value="public:&#xA; TargetInvocationException(System::String ^ message, Exception ^ inner);" />
      <MemberType>Constructor</MemberType>
      <AssemblyInfo>
        <AssemblyName>System.Reflection</AssemblyName>
        <AssemblyVersion>4.0.0.0</AssemblyVersion>
        <AssemblyVersion>4.0.10.0</AssemblyVersion>
        <AssemblyVersion>4.1.0.0</AssemblyVersion>
      </AssemblyInfo>
      <AssemblyInfo>
        <AssemblyName>mscorlib</AssemblyName>
        <AssemblyVersion>2.0.5.0</AssemblyVersion>
        <AssemblyVersion>4.0.0.0</AssemblyVersion>
      </AssemblyInfo>
      <AssemblyInfo>
        <AssemblyName>netstandard</AssemblyName>
        <AssemblyVersion>2.0.0.0</AssemblyVersion>
      </AssemblyInfo>
      <AssemblyInfo>
        <AssemblyName>System.Runtime</AssemblyName>
        <AssemblyVersion>4.2.0.0</AssemblyVersion>
        <AssemblyVersion>4.2.1.0</AssemblyVersion>
      </AssemblyInfo>
      <Parameters>
        <Parameter Name="message" Type="System.String" />
        <Parameter Name="inner" Type="System.Exception" />
      </Parameters>
      <Docs>
        <param name="message">
          <span data-ttu-id="da67f-118">Сообщение об ошибке, указывающее причину создания исключения.</span>
          <span class="sxs-lookup">
            <span data-stu-id="da67f-118">The error message that explains the reason for the exception.</span>
          </span>
        </param>
        <param name="inner">
          <span data-ttu-id="da67f-119">Исключение, которое является причиной текущего исключения.</span>
          <span class="sxs-lookup">
            <span data-stu-id="da67f-119">The exception that is the cause of the current exception.</span>
          </span>
          <span data-ttu-id="da67f-120">Если значение параметра <c>inner</c> не равно <see langword="null" />, текущее исключение возникает в блоке <see langword="catch" />, обрабатывающем внутреннее исключение.</span>
          <span class="sxs-lookup">
            <span data-stu-id="da67f-120">If the <c>inner</c> parameter is not <see langword="null" />, the current exception is raised in a <see langword="catch" /> block that handles the inner exception.</span>
          </span>
        </param>
        <summary>
          <span data-ttu-id="da67f-121">Инициализирует новый экземпляр класса <see cref="T:System.Reflection.TargetInvocationException" /> указанным сообщением об ошибке и ссылкой на внутреннее исключение, вызвавшее данное исключение.</span>
          <span class="sxs-lookup">
            <span data-stu-id="da67f-121">Initializes a new instance of the <see cref="T:System.Reflection.TargetInvocationException" /> class with a specified error message and a reference to the inner exception that is the cause of this exception.</span>
          </span>
        </summary>
        <remarks>
          <format type="text/markdown"><![CDATA[  
  
## Remarks  
 <span data-ttu-id="da67f-122">Исключение, созданное как прямой результат предыдущего исключения, должно содержать в свойстве <xref:System.Exception.InnerException%2A> ссылку на предыдущее исключение.</span><span class="sxs-lookup"><span data-stu-id="da67f-122">An exception that is thrown as a direct result of a previous exception should include a reference to the previous exception in the <xref:System.Exception.InnerException%2A> property.</span></span> <span data-ttu-id="da67f-123">Свойство <xref:System.Exception.InnerException%2A> возвращает значение, переданное конструктору, или значение `null`, если свойство <xref:System.Exception.InnerException%2A> не передает конструктору значение внутреннего исключения.</span><span class="sxs-lookup"><span data-stu-id="da67f-123">The <xref:System.Exception.InnerException%2A> property returns the same value that is passed into the constructor, or `null` if the <xref:System.Exception.InnerException%2A> property does not supply the inner exception value to the constructor.</span></span>  
  
 <span data-ttu-id="da67f-124">В следующей таблице представлены исходные значения свойств экземпляра класса <xref:System.Reflection.TargetInvocationException>.</span><span class="sxs-lookup"><span data-stu-id="da67f-124">The following table shows the initial property values for an instance of <xref:System.Reflection.TargetInvocationException>.</span></span>  
  
|<span data-ttu-id="da67f-125">Свойство.</span><span class="sxs-lookup"><span data-stu-id="da67f-125">Property</span></span>|<span data-ttu-id="da67f-126">Значение</span><span class="sxs-lookup"><span data-stu-id="da67f-126">Value</span></span>|  
|--------------|-----------|  
|<xref:System.Exception.InnerException%2A>|<span data-ttu-id="da67f-127">Ссылка на внутреннее исключение.</span><span class="sxs-lookup"><span data-stu-id="da67f-127">The inner exception reference.</span></span>|  
|<xref:System.Exception.Message%2A>|<span data-ttu-id="da67f-128">Строка сообщения об ошибке.</span><span class="sxs-lookup"><span data-stu-id="da67f-128">The error message string.</span></span>|  
  
 ]]></format>
        </remarks>
        <altmember cref="T:System.Exception" />
      </Docs>
    </Member>
  </Members>
</Type>